---------------------------------------
Begin Slurm Prolog: Mar-03-2025 06:36:51
Job ID:    1494902
User ID:   yzhang3942
Account:   coc
Job name:  evaluateGene
Partition: ice-gpu
QOS:       coe-ice
---------------------------------------
Launching AIsurBL
atl1-1-03-007-33-0.pace.gatech.edu
Lmod has detected the following error: The following module(s) are unknown:
"gcc/13.2.0"

Please check the spelling or version number. Also try "module spider ..."
It is also possible your cache file is out-of-date; it may help to try:
  $ module --ignore_cache load "gcc/13.2.0"

Also make sure that all modulefiles written in TCL start with the string
#%Module




The following have been reloaded with a version change:
  1) cuda/12.6.1 => cuda/12.1.1

/var/lib/slurm/slurmd/job1494902/slurm_script: line 17: /opt/apps/Module/anaconda3/2021.11/bin/activate: No such file or directory
New https://pypi.org/project/ultralytics/8.3.82 available üòÉ Update with 'pip install -U ultralytics'
Ultralytics 8.3.31 üöÄ Python-3.10.16 torch-2.6.0.dev20241112+cu121 CUDA:0 (NVIDIA A100-PCIE-40GB, 40446MiB)
[34m[1mengine/trainer: [0mtask=detect, mode=train, model=network_xXxZLaR13SXPpxabl3bizwbauox.yaml, data=/home/yyu448/yimingyu/code/llm-guided-evolution/sota/ultralytics/kitti.yaml, epochs=100, time=None, patience=100, batch=16, imgsz=640, save=True, save_period=-1, cache=False, device=cuda, workers=8, project=None, name=train3, exist_ok=False, pretrained=True, optimizer=auto, verbose=True, seed=0, deterministic=True, single_cls=False, rect=False, cos_lr=False, close_mosaic=10, resume=False, amp=True, fraction=1.0, profile=False, freeze=None, multi_scale=False, overlap_mask=True, mask_ratio=4, dropout=0.0, val=True, split=val, save_json=False, save_hybrid=False, conf=None, iou=0.7, max_det=300, half=False, dnn=False, plots=True, source=None, vid_stride=1, stream_buffer=False, visualize=False, augment=False, agnostic_nms=False, classes=None, retina_masks=False, embed=None, show=False, save_frames=False, save_txt=False, save_conf=False, save_crop=False, show_labels=True, show_conf=True, show_boxes=True, line_width=None, format=torchscript, keras=False, optimize=False, int8=False, dynamic=False, simplify=True, opset=None, workspace=4, nms=False, lr0=0.01, lrf=0.01, momentum=0.937, weight_decay=0.0005, warmup_epochs=3.0, warmup_momentum=0.8, warmup_bias_lr=0.1, box=7.5, cls=0.5, dfl=1.5, pose=12.0, kobj=1.0, label_smoothing=0.0, nbs=64, hsv_h=0.015, hsv_s=0.7, hsv_v=0.4, degrees=0.0, translate=0.1, scale=0.5, shear=0.0, perspective=0.0, flipud=0.0, fliplr=0.5, bgr=0.0, mosaic=1.0, mixup=0.0, copy_paste=0.0, copy_paste_mode=flip, auto_augment=randaugment, erasing=0.4, crop_fraction=1.0, cfg=None, tracker=botsort.yaml, save_dir=runs/detect/train3
Traceback (most recent call last):
  File "/storage/ice1/0/2/yzhang3942/llm-guided-evolution/sota/ultralytics/ultralytics/engine/trainer.py", line 562, in get_dataset
    data = check_det_dataset(self.args.data)
  File "/storage/ice1/0/2/yzhang3942/llm-guided-evolution/sota/ultralytics/ultralytics/data/utils.py", line 269, in check_det_dataset
    file = check_file(dataset)
  File "/storage/ice1/0/2/yzhang3942/llm-guided-evolution/sota/ultralytics/ultralytics/utils/checks.py", line 520, in check_file
    raise FileNotFoundError(f"'{file}' does not exist")
FileNotFoundError: '/home/yyu448/yimingyu/code/llm-guided-evolution/sota/ultralytics/kitti.yaml' does not exist

The above exception was the direct cause of the following exception:

Traceback (most recent call last):
  File "/storage/ice1/0/2/yzhang3942/llm-guided-evolution/./sota/ultralytics/test.py", line 164, in <module>
    main()
  File "/storage/ice1/0/2/yzhang3942/llm-guided-evolution/./sota/ultralytics/test.py", line 133, in main
    train_results = model.train(
  File "/storage/ice1/0/2/yzhang3942/llm-guided-evolution/sota/ultralytics/ultralytics/engine/model.py", line 796, in train
    self.trainer = (trainer or self._smart_load("trainer"))(overrides=args, _callbacks=self.callbacks)
  File "/storage/ice1/0/2/yzhang3942/llm-guided-evolution/sota/ultralytics/ultralytics/engine/trainer.py", line 133, in __init__
    self.trainset, self.testset = self.get_dataset()
  File "/storage/ice1/0/2/yzhang3942/llm-guided-evolution/sota/ultralytics/ultralytics/engine/trainer.py", line 566, in get_dataset
    raise RuntimeError(emojis(f"Dataset '{clean_url(self.args.data)}' error ‚ùå {e}")) from e
RuntimeError: Dataset '/home/yyu448/yimingyu/code/llm-guided-evolution/sota/ultralytics/kitti.yaml' error ‚ùå '/home/yyu448/yimingyu/code/llm-guided-evolution/sota/ultralytics/kitti.yaml' does not exist
---------------------------------------
Begin Slurm Epilog: Mar-03-2025 06:38:14
Job ID:        1494902
User ID:       yzhang3942
Account:       coc
Job name:      evaluateGene
Resources:     cpu=4,gres/gpu:a100=2,mem=128G,node=1
Rsrc Used:     cput=00:05:36,vmem=0,walltime=00:01:24,mem=2309644K,energy_used=0
Partition:     ice-gpu
QOS:           coe-ice
Nodes:         atl1-1-03-007-33-0
---------------------------------------
